<mujoco model="kangaroo_left_leg">
	<body name="leg_left_1_link" pos="-0.01602 0.08 -0.0585">
		<inertial pos="0.00643148 0.00470584 -0.0104316" quat="0.998799 -0.0118506 -0.0429409 0.0204057" mass="2.89547" diaginertia="0.00237959 0.00215567 0.00154998" />
		<joint name="leg_left_1_joint" pos="0 0 0" axis="0 0 1" limited="true" range="-0.261799 0.698132" />
		<geom class="visual" rgba="0.15625 0.15625 0.15625 1" mesh="leg_1_link" />
		<geom class="collision" mesh="leg_1_link_collision" />
		<body name="leg_left_2_link" pos="0.015024 0 -0.0925">
			<inertial pos="-0.0029278 -9.62074e-05 1.08659e-09" quat="0.500354 0.500354 0.499645 0.499645" mass="0.0905312" diaginertia="3.88542e-05 3.62287e-05 6.1016e-06" />
			<joint name="leg_left_2_joint" pos="0 0 0" axis="0 1 0" limited="true" range="-0.741765 0.741765" />
			<geom class="visual" rgba="0.15625 0.15625 0.15625 1" mesh="leg_2_link" />
			<body name="leg_left_3_link">
				<inertial pos="-0.0331126 0.0492001 -0.030027" quat="0.583313 0.503917 0.383886 0.508375" mass="3.45188" diaginertia="0.0028993 0.00275784 0.00214685" />
				<joint name="leg_left_3_joint" pos="0 0 0" axis="1 0 0" limited="true" range="-0.471239 0.471239" />
				<geom class="visual" rgba="0.15625 0.15625 0.15625 1" mesh="leg_3_link" />
				<geom class="collision" mesh="leg_3_link_collision" />
				<body name="leg_left_length_link" pos="0 0.0669 -0.09" quat="0 0 1 0">
					<inertial pos="0 0 0" mass="0.1" diaginertia="8.58333e-05 8.58333e-05 5e-06" />
					<joint name="leg_left_length_joint" pos="0 0 0" axis="0 0 1" type="slide" limited="true" range="0.131973 0.714166" />
					<geom size="5e-05 0.291097" pos="0 0 -0.291097" type="cylinder" contype="0" conaffinity="0" group="1" density="0" rgba="0.2 0.2 0.2 1" />
					<body name="leg_left_4_link" quat="0 0 1 0">
						<inertial pos="-0.00759995 -6.94998e-09 5.88281e-08" quat="3.61787e-06 0.707107 3.61787e-06 0.707106" mass="0.0905838" diaginertia="2.98863e-05 2.92763e-05 4.05264e-06" />
						<joint name="leg_left_4_joint" pos="0 0 0" axis="0 1 0" limited="true" range="-0.741765 0.741765" />
						<geom class="visual" rgba="0.15625 0.15625 0.15625 1" mesh="leg_6_link" />
						<geom class="collision" mesh="leg_6_link_collision" />
						<body name="leg_left_5_link">
							<inertial pos="0.00594616 -5.92752e-06 -0.0297174" quat="-7.45477e-06 0.594599 -1.35554e-05 0.804022" mass="0.62163" diaginertia="0.00219294 0.0019018 0.000397122" />
							<joint name="leg_left_5_joint" pos="0 0 0" axis="-0.939692 0 0.342021" limited="true" range="-0.471239 0.471239" />
							<geom class="visual" rgba="0.15625 0.15625 0.15625 1" mesh="leg_7_link" />
							<geom class="collision" mesh="leg_7_link_collision" />
						</body>
					</body>
				</body>
				<body name="leg_left_femur_link" pos="0 0.0669 -0.09" quat="0.819152 0 -0.573576 0">
					<inertial pos="0.0527475 0.000135688 -0.146959" quat="0.720223 -0.0942418 -0.0980078 0.680288" mass="3.94567" diaginertia="0.0121138 0.0118241 0.00184947" />
					<joint name="leg_left_femur_joint" pos="0 0 0" axis="0 1 0" limited="true" range="0.174533 1.22173" />
					<geom class="visual" rgba="0.15625 0.15625 0.15625 1" mesh="leg_femur_link" /> 
					<geom class="collision" mesh="leg_femur_link_collision" />
					<body name="leg_left_knee_link" pos="0.129945 0 -0.357092" quat="0.34202 0 0.939693 0">
						<inertial pos="-0.057109 -5.40253e-05 -0.149227" quat="0.697965 0.101468 0.100511 0.701746" mass="1.02438" diaginertia="0.00254149 0.00245871 0.00026224" />
						<joint name="leg_left_knee_joint" pos="0 0 0" axis="0 -1 0" limited="true" range="0.349066 2.44346" />
						<geom class="visual" rgba="0.15625 0.15625 0.15625 1" mesh="leg_tibia_link" /> 
						<geom class="collision" mesh="leg_tibia_link_collision" />
					</body>
				</body>
			</body>
		</body>
	</body>
</mujoco>