<?xml version="1.0" ?>
<!-- =================================================================================== -->
<!-- |    This document was autogenerated by xacro from kangaroo.urdf.xacro            | -->
<!-- |    EDITING THIS FILE BY HAND IS NOT RECOMMENDED                                 | -->
<!-- =================================================================================== -->
<!--

  Copyright (c) 2020, PAL Robotics, S.L.
  All rights reserved.
-->
<robot name="kangaroo" xmlns:controller="http://playerstage.sourceforge.net/gazebo/xmlschema/#controller" xmlns:interface="http://playerstage.sourceforge.net/gazebo/xmlschema/#interface" xmlns:sensor="http://playerstage.sourceforge.net/gazebo/xmlschema/#sensor">
  <!--************************-->
  <!--        BASE_LINK       -->
  <!--************************-->
  <link name="base_link"/>
  <link name="waist">
    <inertial>
      <origin rpy="0 0 0" xyz="-0.060294 0.00050634 0.15428"/>
      <mass value="12.296"/>
      <inertia ixx="0.084937" ixy="-4.4873E-05" ixz="0.0036119" iyy="0.080587" iyz="0.0001781" izz="0.0247"/>
    </inertial>
    <visual>
      <origin rpy="0 0 0" xyz="0 0 0"/>
      <geometry>
        <mesh filename="package://kangaroo_description/meshes/base_link.stl"/>
      </geometry>
      <material name="">
        <color rgba="0.75294 0.75294 0.75294 1"/>
      </material>
    </visual>
    <collision>
      <origin rpy="0 0 0" xyz="0 0 0"/>
      <geometry>
        <mesh filename="package://kangaroo_description/meshes/base_link.stl"/>
      </geometry>
    </collision>
  </link>
  <joint name="base_joint" type="fixed">
    <parent link="base_link"/>
    <child link="waist"/>
  </joint>
  <link name="imu_link">
    <visual>
      <origin rpy="0 0 0" xyz="0 0 0"/>
      <geometry>
        <box size="0.01 0.01 0.01"/>
      </geometry>
    </visual>
  </link>
  <joint name="imu_joint" type="fixed">
    <origin rpy="0.0 3.141592653589793 0.0" xyz="-0.07075 0.0 0.012"/>
    <parent link="base_link"/>
    <child link="imu_link"/>
  </joint>
  <link name="leg_left_1_link">
    <inertial>
      <origin rpy="0 0 0" xyz="0.0461079574284527 -0.000826631128234001 0.00897630312181676"/>
      <mass value="2.49954419149183"/>
      <inertia ixx="0.00151181747940305" ixy="8.83298140320242e-06" ixz="2.17752660615735e-05" iyy="0.00154876023440654" iyz="-1.94449871986378e-05" izz="0.00136106613590181"/>
    </inertial>
    <visual>
      <origin rpy="0 0 0" xyz="0 0 0"/>
      <geometry>
        <mesh filename="package://kangaroo_description/meshes/leg_1_link.stl" scale="1 1 1"/>
      </geometry>
      <material name="">
        <color rgba="0.752941176470588 0.752941176470588 0.752941176470588 1"/>
      </material>
    </visual>
    <collision>
      <origin rpy="0 0 0" xyz="0 0 0"/>
      <geometry>
        <mesh filename="package://kangaroo_description/meshes/leg_1_link.stl" scale="1 1 1"/>
      </geometry>
    </collision>
  </link>
  <joint name="leg_left_1_joint" type="revolute">
    <origin rpy="0 0 0" xyz="-0.01602 0.08 -0.0585"/>
    <parent link="waist"/>
    <child link="leg_left_1_link"/>
    <axis xyz="0 0 1"/>
    <limit effort="100" lower="-0.2617993877991494" upper="0.6981317007977318" velocity="3.87"/>
  </joint>
  <link name="leg_left_2_link">
    <inertial>
      <origin rpy="0 0 0" xyz="-0.00299642516878475 -0.000101293190038279 6.76277450706309E-10"/>
      <mass value="0.0907287903783648"/>
      <inertia ixx="6.10402208807908E-06" ixy="3.54403077254796E-08" ixz="-3.0910293306339E-13" iyy="3.90470919341026E-05" iyz="-1.14069181428674E-12" izz="3.64238433670963E-05"/>
    </inertial>
    <visual>
      <origin rpy="0 0 0" xyz="0 0 0"/>
      <geometry>
        <mesh filename="package://kangaroo_description/meshes/leg_2_link.stl" scale="1 1 1"/>
      </geometry>
      <material name="">
        <color rgba="0.894117647058823 0.913725490196078 0.929411764705882 1"/>
      </material>
    </visual>
  </link>
  <joint name="leg_left_2_joint" type="revolute">
    <origin rpy="0 0 0" xyz="0.016042 0 -0.0925"/>
    <parent link="leg_left_1_link"/>
    <child link="leg_left_2_link"/>
    <axis xyz="0 1 0"/>
    <limit effort="100" lower="-0.7417649320975901" upper="0.7417649320975901" velocity="3.87"/>
  </joint>
  <link name="leg_left_3_link">
    <inertial>
      <origin rpy="0 0 0" xyz="-0.042791492019428 0.0477271400490046 -0.0411219993940296"/>
      <mass value="3.66987205802361"/>
      <inertia ixx="0.00226579365890287" ixy="0.000186528466622377" ixz="-9.4464170720752e-05" iyy="0.00347844100338387" iyz="4.48424073671215e-05" izz="0.00335571040406776"/>
    </inertial>
    <visual>
      <origin rpy="0 0 0" xyz="0 0 0"/>
      <geometry>
        <mesh filename="package://kangaroo_description/meshes/leg_3_link.stl" scale="1 1 1"/>
      </geometry>
      <material name="">
        <color rgba="0.752941176470588 0.752941176470588 0.752941176470588 1"/>
      </material>
    </visual>
    <collision>
      <origin rpy="0 0 0" xyz="0 0 0"/>
      <geometry>
        <mesh filename="package://kangaroo_description/meshes/leg_3_link.stl" scale="1 1 1"/>
      </geometry>
    </collision>
  </link>
  <joint name="leg_left_3_joint" type="revolute">
    <origin rpy="0 0 0" xyz="0 0 0"/>
    <parent link="leg_left_2_link"/>
    <child link="leg_left_3_link"/>
    <axis xyz="1 0 0"/>
    <limit effort="100" lower="-0.47123889803846897" upper="0.47123889803846897" velocity="3.87"/>
  </joint>
  <link name="leg_left_femur_link">
    <inertial>
      <origin rpy="0 0 0" xyz="0.114702002010089 0.000182856660852354 -0.0143986490691173"/>
      <mass value="0.1"/>
      <inertia ixx="1.E-5" ixy="0.0" ixz="0.0" iyy="1.E-5" iyz="0.0" izz="1.E-5"/>
    </inertial>
    <visual>
      <origin rpy="0 0 0" xyz="0 0 0"/>
      <geometry>
        <mesh filename="package://kangaroo_description/meshes/leg_4_link.stl"/>
      </geometry>
      <material name="">
        <color rgba="0.752941176470588 0.752941176470588 0.752941176470588 1"/>
      </material>
    </visual>
    <collision>
      <origin rpy="0 0 0" xyz="0 0 0"/>
      <geometry>
        <mesh filename="package://kangaroo_description/meshes/leg_4_link.stl"/>
      </geometry>
    </collision>
  </link>
  <link name="leg_left_knee_link">
    <inertial>
      <origin rpy="0 0 0" xyz="-0.158662729273678 -8.28192764317226E-05 -0.0337468261967321"/>
      <mass value="0.1"/>
      <inertia ixx="1.E-5" ixy="0.0" ixz="0.0" iyy="1.E-5" iyz="0.0" izz="1.E-5"/>
    </inertial>
    <visual>
      <origin rpy="0 0 0" xyz="0 0 0"/>
      <geometry>
        <mesh filename="package://kangaroo_description/meshes/leg_5_link.stl"/>
      </geometry>
      <material name="">
        <color rgba="0.752941176470588 0.752941176470588 0.752941176470588 1"/>
      </material>
    </visual>
    <collision>
      <origin rpy="0 0 0" xyz="0 0 0"/>
      <geometry>
        <mesh filename="package://kangaroo_description/meshes/leg_5_collision_link.stl"/>
      </geometry>
    </collision>
  </link>
  <link name="leg_left_length_link">
    <inertial>
      <origin rpy="0 0 0" xyz="0.0 0.0 -0.2"/>
      <mass value="6.0"/>
      <inertia ixx="0.05" ixy="0.0" ixz="0.0" iyy="0.05" iyz="0.0" izz="0.016875"/>
    </inertial>
    <visual>
      <origin rpy="0 0 0" xyz="0 0 -0.291096695"/>
      <geometry>
        <cylinder length="0.58219339" radius="0.00005"/>
      </geometry>
      <material name="DarkGrey"/>
    </visual>
  </link>
  <joint name="leg_left_length_joint" type="prismatic">
    <origin rpy="0 3.141592653589793 0" xyz="0 0.0669 -0.09"/>
    <parent link="leg_left_3_link"/>
    <child link="leg_left_length_link"/>
    <axis xyz="0 0 1"/>
    <limit effort="500" lower="0.131973" upper="0.71416639" velocity="10"/>
  </joint>
  <joint name="leg_left_femur_joint" type="revolute">
    <origin rpy="0 -0.17453292519943295 0" xyz="0 0.0669 -0.09"/>
    <parent link="leg_left_3_link"/>
    <child link="leg_left_femur_link"/>
    <axis xyz="0 1 0"/>
    <limit effort="100" lower="0.17453292519943295" upper="1.2217304763960306" velocity="3.87"/>
    <!--mimic joint="leg_left_length_joint" multiplier="1.69435" offset="-0.096145"/-->
  </joint>
  <joint name="leg_left_knee_joint" type="revolute">
    <origin rpy="0 0.3490658503988659 0" xyz="0.37413 0 -0.066509"/>
    <parent link="leg_left_femur_link"/>
    <child link="leg_left_knee_link"/>
    <axis xyz="0 -1 0"/>
    <limit effort="100" lower="0.3490658503988659" upper="2.443460952792061" velocity="3.87"/>
    <!--mimic joint="leg_left_length_joint" multiplier="3.38877" offset="-0.19229"/-->
  </joint>
  <link name="leg_left_4_link">
    <inertial>
      <origin rpy="0 0 0" xyz="-0.00714160332877733 4.8311277200952E-09 0.00259941265068991"/>
      <mass value="0.0905836559788966"/>
      <inertia ixx="7.07461991271062E-06" ixy="-1.86951004827933E-12" ixz="8.30282143898823E-06" iyy="2.92762498059213E-05" iyz="1.82895645239997E-11" izz="2.68643074366886E-05"/>
    </inertial>
    <visual>
      <origin rpy="0 0 0" xyz="0 0 0"/>
      <geometry>
        <mesh filename="package://kangaroo_description/meshes/leg_6_link.stl"/>
      </geometry>
      <material name="">
        <color rgba="0.752941176470588 0.752941176470588 0.752941176470588 1"/>
      </material>
    </visual>
  </link>
  <joint name="leg_left_4_joint" type="revolute">
    <origin rpy="0 3.141592653589793 0" xyz="0.0 0 0.0"/>
    <parent link="leg_left_length_link"/>
    <child link="leg_left_4_link"/>
    <axis xyz="0 1 0"/>
    <limit effort="100" lower="-0.7417649320975901" upper="0.7417649320975901" velocity="3.87"/>
  </joint>
  <link name="leg_left_5_link">
    <inertial>
      <origin rpy="0 0 0" xyz="0.0177425915954867 -3.67950153736807E-05 -0.0172694732454237"/>
      <mass value="0.394418327358563"/>
      <inertia ixx="0.000228382894016579" ixy="-2.56621760255351E-07" ixz="4.1179623691202E-05" iyy="0.00108653696539759" iyz="7.85648127231571E-09" izz="0.0012643765698811"/>
    </inertial>
    <visual>
      <origin rpy="0 0 0" xyz="0 0 0"/>
      <geometry>
        <mesh filename="package://kangaroo_description/meshes/leg_7_link.stl"/>
      </geometry>
      <material name="">
        <color rgba="0.752941176470588 0.752941176470588 0.752941176470588 1"/>
      </material>
    </visual>
    <collision>
      <origin rpy="0 0 0" xyz="0.035 0 -0.02"/>
      <geometry>
        <box size="0.21 0.09 0.025"/>
      </geometry>
    </collision>
  </link>
  <joint name="leg_left_5_joint" type="revolute">
    <origin rpy="0 0 0" xyz="0 0 0"/>
    <parent link="leg_left_4_link"/>
    <child link="leg_left_5_link"/>
    <!--axis xyz="-0.93969 0 0.34202"/-->
    <axis xyz="-1 0 0"/>
    <limit effort="100" lower="-0.47123889803846897" upper="0.47123889803846897" velocity="3.87"/>
  </joint>
  <link name="left_sole_link"/>
  <joint name="left_sole_fix_joint" type="fixed">
    <parent link="leg_left_5_link"/>
    <child link="left_sole_link"/>
    <origin rpy="0 0 0" xyz="0.028 0.0 -0.029"/>
    <axis xyz="1 0 0"/>
  </joint>
  <transmission name="leg_left_4_transmission">
    <type>transmission_interface/SimpleTransmission</type>
    <actuator name="leg_left_4_motor">
      <hardwareInterface>hardware_interface/PositionJointInterface</hardwareInterface>
      <hardwareInterface>hardware_interface/EffortJointInterface</hardwareInterface>
      <hardwareInterface>hardware_interface/JointStateInterface</hardwareInterface>
      <mechanicalReduction>1.0</mechanicalReduction>
    </actuator>
    <joint name="leg_left_4_joint">
      <hardwareInterface>hardware_interface/PositionJointInterface</hardwareInterface>
      <hardwareInterface>hardware_interface/EffortJointInterface</hardwareInterface>
      <hardwareInterface>hardware_interface/JointStateInterface</hardwareInterface>
    </joint>
  </transmission>
  <transmission name="leg_left_5_transmission">
    <type>transmission_interface/SimpleTransmission</type>
    <actuator name="leg_left_5_motor">
      <hardwareInterface>hardware_interface/PositionJointInterface</hardwareInterface>
      <hardwareInterface>hardware_interface/EffortJointInterface</hardwareInterface>
      <hardwareInterface>hardware_interface/JointStateInterface</hardwareInterface>
      <mechanicalReduction>1.0</mechanicalReduction>
    </actuator>
    <joint name="leg_left_5_joint">
      <hardwareInterface>hardware_interface/PositionJointInterface</hardwareInterface>
      <hardwareInterface>hardware_interface/EffortJointInterface</hardwareInterface>
      <hardwareInterface>hardware_interface/JointStateInterface</hardwareInterface>
    </joint>
  </transmission>
  <!--     <transmission name="leg_${side}_transmission">
      <type>pal_transmissions/AnkleCustomTransmission</type>
      <actuator name="leg_${side}_${roll_joint}_motor">
        <role>right_actuator</role>
        <param_ns>/ankle_params</param_ns>
      </actuator>
      <actuator name="leg_${side}_${pitch_joint}_motor">
        <role>left_actuator</role>
      </actuator>
      <actuator name="${read_actuator}">
        <role>leg_length</role>
        <param_ns>/leg_params</param_ns>
      </actuator>
      <joint name="leg_${side}_${roll_joint}_joint">
        <role>roll_joint</role>
        <offset> 0.0 </offset>
        <hardwareInterface>hardware_interface/PositionJointInterface</hardwareInterface>
        <hardwareInterface>hardware_interface/EffortJointInterface</hardwareInterface>
      </joint>
      <joint name="leg_${side}_${pitch_joint}_joint">
        <role>pitch_joint</role>
        <offset> 0.0 </offset>
        <hardwareInterface>hardware_interface/PositionJointInterface</hardwareInterface>
        <hardwareInterface>hardware_interface/EffortJointInterface</hardwareInterface>
      </joint>
    </transmission> -->
  <gazebo reference="leg_left_4_joint">
    <implicitSpringDamper>1</implicitSpringDamper>
  </gazebo>
  <gazebo reference="leg_left_5_joint">
    <implicitSpringDamper>1</implicitSpringDamper>
    <provideFeedback>1</provideFeedback>
  </gazebo>
  <gazebo reference="leg_left_4_link">
    <mu1>0.9</mu1>
    <mu2>0.9</mu2>
    <implicitSpringDamper>1</implicitSpringDamper>
    <material>Gazebo/FlatWhite</material>
  </gazebo>
  <!--
   <gazebo reference="leg_${side}_${roll_joint}_link">
     <mu1>0.9</mu1>
     <mu2>0.9</mu2>
     <implicitSpringDamper>1</implicitSpringDamper>
     <material>Gazebo/FlatWhite</material>
   </gazebo>  -->
  <gazebo reference="leg_left_5_link">
    <kp>1000000.0</kp>
    <!-- 1000000 -->
    <kd>100.0</kd>
    <mu1>1.0</mu1>
    <mu2>1.0</mu2>
    <fdir1>1 0 0</fdir1>
    <maxVel>1.0</maxVel>
    <minDepth>0.00</minDepth>
    <implicitSpringDamper>1</implicitSpringDamper>
    <provideFeedback>1</provideFeedback>
    <material>Gazebo/FlatWhite</material>
  </gazebo>
  <!--
    <gazebo reference="leg_{side}_${pitch_joint}_link">
     <kp>1000.0</kp>
      <kd>10.0</kd>
      <mu1>1.0</mu1>
      <mu2>1.0</mu2>
      <fdir1>1 0 0</fdir1>
      <fdir2>0 1 0</fdir2>
      <maxVel>1.0</maxVel>
      <minDepth>0.00</minDepth>
      <implicitSpringDamper>1</implicitSpringDamper>
      <provideFeedback>1</provideFeedback>
      <material>Gazebo/FlatWhite</material>
    </gazebo>
    -->
  <transmission name="leg_left_transmission_yaw">
    <type>transmission_interface/SimpleTransmission</type>
    <actuator name="leg_left_1_motor">
      <mechanicalReduction>1.0</mechanicalReduction>
    </actuator>
    <joint name="leg_left_1_joint">
      <hardwareInterface>hardware_interface/PositionJointInterface</hardwareInterface>
      <hardwareInterface>hardware_interface/EffortJointInterface</hardwareInterface>
    </joint>
  </transmission>
  <transmission name="leg_left_transmission_roll_pitch">
    <type>pal_transmissions/HipCustomTransmission</type>
    <actuator name="leg_left_3_motor">
      <role>actuator1</role>
      <virtual_linear_actuator>
        <screw_lead> 0.005 </screw_lead>
        <efficiency> 0.9 </efficiency>
        <limits>
          <position>
            <min> 0.0 </min>
            <max> 0.10 </max>
          </position>
          <velocity>
            <min> -0.3 </min>
            <max> 0.3 </max>
          </velocity>
        </limits>
      </virtual_linear_actuator>
      <mechanicalReduction>1.0</mechanicalReduction>
    </actuator>
    <actuator name="leg_left_2_motor">
      <role>actuator2</role>
      <virtual_linear_actuator>
        <screw_lead> 0.005 </screw_lead>
        <efficiency> 0.9 </efficiency>
        <limits>
          <position>
            <min> 0.0 </min>
            <max> 0.10 </max>
          </position>
          <velocity>
            <min> -0.3 </min>
            <max> 0.3 </max>
          </velocity>
        </limits>
      </virtual_linear_actuator>
      <mechanicalReduction>1.0</mechanicalReduction>
    </actuator>
    <joint name="leg_left_3_joint">
      <role>joint1</role>
      <limits>
        <position>
          <min> -0.47123889803846897 </min>
          <max> 0.47123889803846897 </max>
        </position>
      </limits>
      <configuration>
        <offset_x> 0.0035 </offset_x>
        <offset_y> 0.0051 </offset_y>
        <projected_distance> 0.17650 </projected_distance>
        <dx> 0.0035 </dx>
        <dy> 0.0060 </dy>
      </configuration>
      <hardwareInterface>hardware_interface/PositionJointInterface</hardwareInterface>
      <hardwareInterface>hardware_interface/EffortJointInterface</hardwareInterface>
    </joint>
    <joint name="leg_left_2_joint">
      <role>joint2</role>
      <limits>
        <position>
          <min> -0.7417649320975901 </min>
          <max> 0.7417649320975901 </max>
        </position>
      </limits>
      <hardwareInterface>hardware_interface/PositionJointInterface</hardwareInterface>
      <hardwareInterface>hardware_interface/EffortJointInterface</hardwareInterface>
    </joint>
  </transmission>
  <transmission name="leg_left_leg_length_trans">
    <type>pal_transmissions/LegCustomTransmission</type>
    <actuator name="leg_left_length_motor">
      </actuator>
    <joint name="leg_left_length_joint">
      <joint_type> leg_length </joint_type>
      <param_ns> /leg_params </param_ns>
      <offset> 0.0 </offset>
      <hardwareInterface>hardware_interface/PositionJointInterface</hardwareInterface>
      <hardwareInterface>hardware_interface/EffortJointInterface</hardwareInterface>
      <hardwareInterface>hardware_interface/JointStateInterface</hardwareInterface>
    </joint>
  </transmission>
  <gazebo reference="leg_left_1_link">
    <mu1>0.9</mu1>
    <mu2>0.9</mu2>
  </gazebo>
  <gazebo reference="leg_left_2_link">
    <mu1>0.9</mu1>
    <mu2>0.9</mu2>
  </gazebo>
  <gazebo reference="leg_left_3_link">
    <mu1>0.9</mu1>
    <mu2>0.9</mu2>
  </gazebo>
  <gazebo reference="leg_left_length_link">
    <mu1>0.9</mu1>
    <mu2>0.9</mu2>
  </gazebo>
  <!-- <gazebo reference="leg_${side}_4_link">
      <mu1>0.9</mu1>
      <mu2>0.9</mu2>
    </gazebo>
    <gazebo reference="leg_${side}_5_link">
      <mu1>0.9</mu1>
      <mu2>0.9</mu2>
    </gazebo> -->
  <gazebo reference="leg_left_1_joint">
    <implicitSpringDamper>1</implicitSpringDamper>
  </gazebo>
  <gazebo reference="leg_left_2_joint">
    <implicitSpringDamper>1</implicitSpringDamper>
  </gazebo>
  <gazebo reference="leg_left_3_joint">
    <implicitSpringDamper>1</implicitSpringDamper>
  </gazebo>
  <!-- <gazebo reference="leg_${side}_4_joint">
      <implicitSpringDamper>1</implicitSpringDamper>
   </gazebo>
   <gazebo reference="leg_${side}_5_joint">
      <implicitSpringDamper>1</implicitSpringDamper>
   </gazebo> -->
  <gazebo reference="leg_left_length_link">
    <implicitSpringDamper>1</implicitSpringDamper>
  </gazebo>
  <gazebo reference="leg_left_1_link">
    <material>Gazebo/FlatWhite</material>
  </gazebo>
  <gazebo reference="leg_left_2_link">
    <material>Gazebo/FlatWhite</material>
  </gazebo>
  <gazebo reference="leg_left_3_link">
    <material>Gazebo/FlatWhite</material>
  </gazebo>
  <!-- <gazebo reference="leg_${side}_4_link">
     <material>Gazebo/FlatBlack</material>
   </gazebo>
   <gazebo reference="leg_${side}_5_link">
     <material>Gazebo/FlatBlack</material>
   </gazebo> -->
  <gazebo reference="leg_left_length_link">
    <material>Gazebo/FlatBlack</material>
  </gazebo>
  <gazebo>
    <plugin filename="libroboticsgroup_gazebo_mimic_joint_plugin.so" name="mimic_joint_plugin">
      <joint>leg_left_length_joint</joint>
      <mimicJoint>leg_left_knee_joint</mimicJoint>
      <multiplier>3.38877</multiplier>
      <offset>-0.19229</offset>
      <sensitiveness>0.0</sensitiveness>
      <!-- if absolute difference between setpoint and process value is below this threshold, do nothing; 0.0 = disable [rad] -->
      <maxEffort>100.0</maxEffort>
    </plugin>
  </gazebo>
  <gazebo>
    <plugin filename="libroboticsgroup_gazebo_mimic_joint_plugin.so" name="mimic_joint_plugin">
      <joint>leg_left_length_joint</joint>
      <mimicJoint>leg_left_femur_joint</mimicJoint>
      <multiplier>1.69435</multiplier>
      <offset>-0.096145</offset>
      <sensitiveness>0.0</sensitiveness>
      <!-- if absolute difference between setpoint and process value is below this threshold, do nothing; 0.0 = disable [rad] -->
      <maxEffort>100.0</maxEffort>
    </plugin>
  </gazebo>
  <link name="leg_right_1_link">
    <inertial>
      <origin rpy="0 0 0" xyz="0.0461079574284527 0.000826631128234001 0.00897630312181676"/>
      <mass value="2.49954419149183"/>
      <inertia ixx="0.00151181747940305" ixy="-8.83298140320242e-06" ixz="-2.17752660615735e-05" iyy="0.00154876023440654" iyz="1.94449871986378e-05" izz="0.00136106613590181"/>
    </inertial>
    <visual>
      <origin rpy="0 0 0" xyz="0 0 0"/>
      <geometry>
        <mesh filename="package://kangaroo_description/meshes/leg_1_link.stl" scale="1 -1 1"/>
      </geometry>
      <material name="">
        <color rgba="0.752941176470588 0.752941176470588 0.752941176470588 1"/>
      </material>
    </visual>
    <collision>
      <origin rpy="0 0 0" xyz="0 0 0"/>
      <geometry>
        <mesh filename="package://kangaroo_description/meshes/leg_1_link.stl" scale="1 -1 1"/>
      </geometry>
    </collision>
  </link>
  <joint name="leg_right_1_joint" type="revolute">
    <origin rpy="0 0 0" xyz="-0.01602 -0.08 -0.0585"/>
    <parent link="waist"/>
    <child link="leg_right_1_link"/>
    <axis xyz="0 0 1"/>
    <limit effort="100" lower="-0.6981317007977318" upper="0.2617993877991494" velocity="3.87"/>
  </joint>
  <link name="leg_right_2_link">
    <inertial>
      <origin rpy="0 0 0" xyz="-0.00299642516878475 -0.000101293190038279 6.76277450706309E-10"/>
      <mass value="0.0907287903783648"/>
      <inertia ixx="6.10402208807908E-06" ixy="3.54403077254796E-08" ixz="-3.0910293306339E-13" iyy="3.90470919341026E-05" iyz="-1.14069181428674E-12" izz="3.64238433670963E-05"/>
    </inertial>
    <visual>
      <origin rpy="0 0 0" xyz="0 0 0"/>
      <geometry>
        <mesh filename="package://kangaroo_description/meshes/leg_2_link.stl" scale="1 -1 1"/>
      </geometry>
      <material name="">
        <color rgba="0.894117647058823 0.913725490196078 0.929411764705882 1"/>
      </material>
    </visual>
  </link>
  <joint name="leg_right_2_joint" type="revolute">
    <origin rpy="0 0 0" xyz="0.016042 0 -0.0925"/>
    <parent link="leg_right_1_link"/>
    <child link="leg_right_2_link"/>
    <axis xyz="0 1 0"/>
    <limit effort="100" lower="-0.7417649320975901" upper="0.7417649320975901" velocity="3.87"/>
  </joint>
  <link name="leg_right_3_link">
    <inertial>
      <origin rpy="0 0 0" xyz="-0.042791492019428 -0.0477271400490046 -0.0411219993940296"/>
      <mass value="3.66987205802361"/>
      <inertia ixx="0.00226579365890287" ixy="-0.000186528466622377" ixz="9.4464170720752e-05" iyy="0.00347844100338387" iyz="-4.48424073671215e-05" izz="0.00335571040406776"/>
    </inertial>
    <visual>
      <origin rpy="0 0 0" xyz="0 0 0"/>
      <geometry>
        <mesh filename="package://kangaroo_description/meshes/leg_3_link.stl" scale="1 -1 1"/>
      </geometry>
      <material name="">
        <color rgba="0.752941176470588 0.752941176470588 0.752941176470588 1"/>
      </material>
    </visual>
    <collision>
      <origin rpy="0 0 0" xyz="0 0 0"/>
      <geometry>
        <mesh filename="package://kangaroo_description/meshes/leg_3_link.stl" scale="1 -1 1"/>
      </geometry>
    </collision>
  </link>
  <joint name="leg_right_3_joint" type="revolute">
    <origin rpy="0 0 0" xyz="0 0 0"/>
    <parent link="leg_right_2_link"/>
    <child link="leg_right_3_link"/>
    <axis xyz="1 0 0"/>
    <limit effort="100" lower="-0.47123889803846897" upper="0.47123889803846897" velocity="3.87"/>
  </joint>
  <link name="leg_right_femur_link">
    <inertial>
      <origin rpy="0 0 0" xyz="0.114702002010089 0.000182856660852354 -0.0143986490691173"/>
      <mass value="0.1"/>
      <inertia ixx="1.E-5" ixy="0.0" ixz="0.0" iyy="1.E-5" iyz="0.0" izz="1.E-5"/>
    </inertial>
    <visual>
      <origin rpy="0 0 0" xyz="0 0 0"/>
      <geometry>
        <mesh filename="package://kangaroo_description/meshes/leg_4_link.stl"/>
      </geometry>
      <material name="">
        <color rgba="0.752941176470588 0.752941176470588 0.752941176470588 1"/>
      </material>
    </visual>
    <collision>
      <origin rpy="0 0 0" xyz="0 0 0"/>
      <geometry>
        <mesh filename="package://kangaroo_description/meshes/leg_4_link.stl"/>
      </geometry>
    </collision>
  </link>
  <link name="leg_right_knee_link">
    <inertial>
      <origin rpy="0 0 0" xyz="-0.158662729273678 -8.28192764317226E-05 -0.0337468261967321"/>
      <mass value="0.1"/>
      <inertia ixx="1.E-5" ixy="0.0" ixz="0.0" iyy="1.E-5" iyz="0.0" izz="1.E-5"/>
    </inertial>
    <visual>
      <origin rpy="0 0 0" xyz="0 0 0"/>
      <geometry>
        <mesh filename="package://kangaroo_description/meshes/leg_5_link.stl"/>
      </geometry>
      <material name="">
        <color rgba="0.752941176470588 0.752941176470588 0.752941176470588 1"/>
      </material>
    </visual>
    <collision>
      <origin rpy="0 0 0" xyz="0 0 0"/>
      <geometry>
        <mesh filename="package://kangaroo_description/meshes/leg_5_collision_link.stl"/>
      </geometry>
    </collision>
  </link>
  <link name="leg_right_length_link">
    <inertial>
      <origin rpy="0 0 0" xyz="0.0 0.0 -0.2"/>
      <mass value="6.0"/>
      <inertia ixx="0.05" ixy="0.0" ixz="0.0" iyy="0.05" iyz="0.0" izz="0.016875"/>
    </inertial>
    <visual>
      <origin rpy="0 0 0" xyz="0 0 -0.291096695"/>
      <geometry>
        <cylinder length="0.58219339" radius="0.00005"/>
      </geometry>
      <material name="DarkGrey"/>
    </visual>
  </link>
  <joint name="leg_right_length_joint" type="prismatic">
    <origin rpy="0 3.141592653589793 0" xyz="0 -0.0669 -0.09"/>
    <parent link="leg_right_3_link"/>
    <child link="leg_right_length_link"/>
    <axis xyz="0 0 1"/>
    <limit effort="500" lower="0.131973" upper="0.71416639" velocity="10"/>
  </joint>
  <joint name="leg_right_femur_joint" type="revolute">
    <origin rpy="0 -0.17453292519943295 0" xyz="0 -0.0669 -0.09"/>
    <parent link="leg_right_3_link"/>
    <child link="leg_right_femur_link"/>
    <axis xyz="0 1 0"/>
    <limit effort="100" lower="0.17453292519943295" upper="1.2217304763960306" velocity="3.87"/>
    <!--mimic joint="leg_right_length_joint" multiplier="1.69435" offset="-0.096145"/-->
  </joint>
  <joint name="leg_right_knee_joint" type="revolute">
    <origin rpy="0 0.3490658503988659 0" xyz="0.37413 0 -0.066509"/>
    <parent link="leg_right_femur_link"/>
    <child link="leg_right_knee_link"/>
    <axis xyz="0 -1 0"/>
    <limit effort="100" lower="0.3490658503988659" upper="2.443460952792061" velocity="3.87"/>
    <!--mimic joint="leg_right_length_joint" multiplier="3.38877" offset="-0.19229"/-->
  </joint>
  <link name="leg_right_4_link">
    <inertial>
      <origin rpy="0 0 0" xyz="-0.00714160332877733 4.8311277200952E-09 0.00259941265068991"/>
      <mass value="0.0905836559788966"/>
      <inertia ixx="7.07461991271062E-06" ixy="-1.86951004827933E-12" ixz="8.30282143898823E-06" iyy="2.92762498059213E-05" iyz="1.82895645239997E-11" izz="2.68643074366886E-05"/>
    </inertial>
    <visual>
      <origin rpy="0 0 0" xyz="0 0 0"/>
      <geometry>
        <mesh filename="package://kangaroo_description/meshes/leg_6_link.stl"/>
      </geometry>
      <material name="">
        <color rgba="0.752941176470588 0.752941176470588 0.752941176470588 1"/>
      </material>
    </visual>
  </link>
  <joint name="leg_right_4_joint" type="revolute">
    <origin rpy="0 3.141592653589793 0" xyz="0.0 0 0.0"/>
    <parent link="leg_right_length_link"/>
    <child link="leg_right_4_link"/>
    <axis xyz="0 1 0"/>
    <limit effort="100" lower="-0.7417649320975901" upper="0.7417649320975901" velocity="3.87"/>
  </joint>
  <link name="leg_right_5_link">
    <inertial>
      <origin rpy="0 0 0" xyz="0.0177425915954867 -3.67950153736807E-05 -0.0172694732454237"/>
      <mass value="0.394418327358563"/>
      <inertia ixx="0.000228382894016579" ixy="-2.56621760255351E-07" ixz="4.1179623691202E-05" iyy="0.00108653696539759" iyz="7.85648127231571E-09" izz="0.0012643765698811"/>
    </inertial>
    <visual>
      <origin rpy="0 0 0" xyz="0 0 0"/>
      <geometry>
        <mesh filename="package://kangaroo_description/meshes/leg_7_link.stl"/>
      </geometry>
      <material name="">
        <color rgba="0.752941176470588 0.752941176470588 0.752941176470588 1"/>
      </material>
    </visual>
    <collision>
      <origin rpy="0 0 0" xyz="0.035 0 -0.02"/>
      <geometry>
        <box size="0.21 0.09 0.025"/>
      </geometry>
    </collision>
  </link>
  <joint name="leg_right_5_joint" type="revolute">
    <origin rpy="0 0 0" xyz="0 0 0"/>
    <parent link="leg_right_4_link"/>
    <child link="leg_right_5_link"/>
    <!--axis xyz="-0.93969 0 0.34202"/-->
    <axis xyz="-1. 0 0."/>
    <limit effort="100" lower="-0.47123889803846897" upper="0.47123889803846897" velocity="3.87"/>
  </joint>
  <link name="right_sole_link"/>
  <joint name="right_sole_fix_joint" type="fixed">
    <parent link="leg_right_5_link"/>
    <child link="right_sole_link"/>
    <origin rpy="0 0 0" xyz="0.028 0.0 -0.029"/>
    <axis xyz="1 0 0"/>
  </joint>
  <transmission name="leg_right_4_transmission">
    <type>transmission_interface/SimpleTransmission</type>
    <actuator name="leg_right_4_motor">
      <hardwareInterface>hardware_interface/PositionJointInterface</hardwareInterface>
      <hardwareInterface>hardware_interface/EffortJointInterface</hardwareInterface>
      <hardwareInterface>hardware_interface/JointStateInterface</hardwareInterface>
      <mechanicalReduction>1.0</mechanicalReduction>
    </actuator>
    <joint name="leg_right_4_joint">
      <hardwareInterface>hardware_interface/PositionJointInterface</hardwareInterface>
      <hardwareInterface>hardware_interface/EffortJointInterface</hardwareInterface>
      <hardwareInterface>hardware_interface/JointStateInterface</hardwareInterface>
    </joint>
  </transmission>
  <transmission name="leg_right_5_transmission">
    <type>transmission_interface/SimpleTransmission</type>
    <actuator name="leg_right_5_motor">
      <hardwareInterface>hardware_interface/PositionJointInterface</hardwareInterface>
      <hardwareInterface>hardware_interface/EffortJointInterface</hardwareInterface>
      <hardwareInterface>hardware_interface/JointStateInterface</hardwareInterface>
      <mechanicalReduction>1.0</mechanicalReduction>
    </actuator>
    <joint name="leg_right_5_joint">
      <hardwareInterface>hardware_interface/PositionJointInterface</hardwareInterface>
      <hardwareInterface>hardware_interface/EffortJointInterface</hardwareInterface>
      <hardwareInterface>hardware_interface/JointStateInterface</hardwareInterface>
    </joint>
  </transmission>
  <!--     <transmission name="leg_${side}_transmission">
      <type>pal_transmissions/AnkleCustomTransmission</type>
      <actuator name="leg_${side}_${roll_joint}_motor">
        <role>right_actuator</role>
        <param_ns>/ankle_params</param_ns>
      </actuator>
      <actuator name="leg_${side}_${pitch_joint}_motor">
        <role>left_actuator</role>
      </actuator>
      <actuator name="${read_actuator}">
        <role>leg_length</role>
        <param_ns>/leg_params</param_ns>
      </actuator>
      <joint name="leg_${side}_${roll_joint}_joint">
        <role>roll_joint</role>
        <offset> 0.0 </offset>
        <hardwareInterface>hardware_interface/PositionJointInterface</hardwareInterface>
        <hardwareInterface>hardware_interface/EffortJointInterface</hardwareInterface>
      </joint>
      <joint name="leg_${side}_${pitch_joint}_joint">
        <role>pitch_joint</role>
        <offset> 0.0 </offset>
        <hardwareInterface>hardware_interface/PositionJointInterface</hardwareInterface>
        <hardwareInterface>hardware_interface/EffortJointInterface</hardwareInterface>
      </joint>
    </transmission> -->
  <gazebo reference="leg_right_4_joint">
    <implicitSpringDamper>1</implicitSpringDamper>
  </gazebo>
  <gazebo reference="leg_right_5_joint">
    <implicitSpringDamper>1</implicitSpringDamper>
    <provideFeedback>1</provideFeedback>
  </gazebo>
  <gazebo reference="leg_right_4_link">
    <mu1>0.9</mu1>
    <mu2>0.9</mu2>
    <implicitSpringDamper>1</implicitSpringDamper>
    <material>Gazebo/FlatWhite</material>
  </gazebo>
  <!--
   <gazebo reference="leg_${side}_${roll_joint}_link">
     <mu1>0.9</mu1>
     <mu2>0.9</mu2>
     <implicitSpringDamper>1</implicitSpringDamper>
     <material>Gazebo/FlatWhite</material>
   </gazebo>  -->
  <gazebo reference="leg_right_5_link">
    <kp>1000000.0</kp>
    <!-- 1000000 -->
    <kd>100.0</kd>
    <mu1>1.0</mu1>
    <mu2>1.0</mu2>
    <fdir1>1 0 0</fdir1>
    <maxVel>1.0</maxVel>
    <minDepth>0.00</minDepth>
    <implicitSpringDamper>1</implicitSpringDamper>
    <provideFeedback>1</provideFeedback>
    <material>Gazebo/FlatWhite</material>
  </gazebo>
  <!--
    <gazebo reference="leg_{side}_${pitch_joint}_link">
     <kp>1000.0</kp>
      <kd>10.0</kd>
      <mu1>1.0</mu1>
      <mu2>1.0</mu2>
      <fdir1>1 0 0</fdir1>
      <fdir2>0 1 0</fdir2>
      <maxVel>1.0</maxVel>
      <minDepth>0.00</minDepth>
      <implicitSpringDamper>1</implicitSpringDamper>
      <provideFeedback>1</provideFeedback>
      <material>Gazebo/FlatWhite</material>
    </gazebo>
    -->
  <transmission name="leg_right_transmission_yaw">
    <type>transmission_interface/SimpleTransmission</type>
    <actuator name="leg_right_1_motor">
      <mechanicalReduction>1.0</mechanicalReduction>
    </actuator>
    <joint name="leg_right_1_joint">
      <hardwareInterface>hardware_interface/PositionJointInterface</hardwareInterface>
      <hardwareInterface>hardware_interface/EffortJointInterface</hardwareInterface>
    </joint>
  </transmission>
  <transmission name="leg_right_transmission_roll_pitch">
    <type>pal_transmissions/HipCustomTransmission</type>
    <actuator name="leg_right_3_motor">
      <role>actuator1</role>
      <virtual_linear_actuator>
        <screw_lead> 0.005 </screw_lead>
        <efficiency> 0.9 </efficiency>
        <limits>
          <position>
            <min> 0.0 </min>
            <max> 0.10 </max>
          </position>
          <velocity>
            <min> -0.3 </min>
            <max> 0.3 </max>
          </velocity>
        </limits>
      </virtual_linear_actuator>
      <mechanicalReduction>1.0</mechanicalReduction>
    </actuator>
    <actuator name="leg_right_2_motor">
      <role>actuator2</role>
      <virtual_linear_actuator>
        <screw_lead> 0.005 </screw_lead>
        <efficiency> 0.9 </efficiency>
        <limits>
          <position>
            <min> 0.0 </min>
            <max> 0.10 </max>
          </position>
          <velocity>
            <min> -0.3 </min>
            <max> 0.3 </max>
          </velocity>
        </limits>
      </virtual_linear_actuator>
      <mechanicalReduction>1.0</mechanicalReduction>
    </actuator>
    <joint name="leg_right_3_joint">
      <role>joint1</role>
      <limits>
        <position>
          <min> -0.47123889803846897 </min>
          <max> 0.47123889803846897 </max>
        </position>
      </limits>
      <configuration>
        <offset_x> 0.0035 </offset_x>
        <offset_y> 0.0051 </offset_y>
        <projected_distance> 0.17650 </projected_distance>
        <dx> 0.0035 </dx>
        <dy> 0.0060 </dy>
      </configuration>
      <hardwareInterface>hardware_interface/PositionJointInterface</hardwareInterface>
      <hardwareInterface>hardware_interface/EffortJointInterface</hardwareInterface>
    </joint>
    <joint name="leg_right_2_joint">
      <role>joint2</role>
      <limits>
        <position>
          <min> -0.7417649320975901 </min>
          <max> 0.7417649320975901 </max>
        </position>
      </limits>
      <hardwareInterface>hardware_interface/PositionJointInterface</hardwareInterface>
      <hardwareInterface>hardware_interface/EffortJointInterface</hardwareInterface>
    </joint>
  </transmission>
  <transmission name="leg_right_leg_length_trans">
    <type>pal_transmissions/LegCustomTransmission</type>
    <actuator name="leg_right_length_motor">
      </actuator>
    <joint name="leg_right_length_joint">
      <joint_type> leg_length </joint_type>
      <param_ns> /leg_params </param_ns>
      <offset> 0.0 </offset>
      <hardwareInterface>hardware_interface/PositionJointInterface</hardwareInterface>
      <hardwareInterface>hardware_interface/EffortJointInterface</hardwareInterface>
      <hardwareInterface>hardware_interface/JointStateInterface</hardwareInterface>
    </joint>
  </transmission>
  <gazebo reference="leg_right_1_link">
    <mu1>0.9</mu1>
    <mu2>0.9</mu2>
  </gazebo>
  <gazebo reference="leg_right_2_link">
    <mu1>0.9</mu1>
    <mu2>0.9</mu2>
  </gazebo>
  <gazebo reference="leg_right_3_link">
    <mu1>0.9</mu1>
    <mu2>0.9</mu2>
  </gazebo>
  <gazebo reference="leg_right_length_link">
    <mu1>0.9</mu1>
    <mu2>0.9</mu2>
  </gazebo>
  <!-- <gazebo reference="leg_${side}_4_link">
      <mu1>0.9</mu1>
      <mu2>0.9</mu2>
    </gazebo>
    <gazebo reference="leg_${side}_5_link">
      <mu1>0.9</mu1>
      <mu2>0.9</mu2>
    </gazebo> -->
  <gazebo reference="leg_right_1_joint">
    <implicitSpringDamper>1</implicitSpringDamper>
  </gazebo>
  <gazebo reference="leg_right_2_joint">
    <implicitSpringDamper>1</implicitSpringDamper>
  </gazebo>
  <gazebo reference="leg_right_3_joint">
    <implicitSpringDamper>1</implicitSpringDamper>
  </gazebo>
  <!-- <gazebo reference="leg_${side}_4_joint">
      <implicitSpringDamper>1</implicitSpringDamper>
   </gazebo>
   <gazebo reference="leg_${side}_5_joint">
      <implicitSpringDamper>1</implicitSpringDamper>
   </gazebo> -->
  <gazebo reference="leg_right_length_link">
    <implicitSpringDamper>1</implicitSpringDamper>
  </gazebo>
  <gazebo reference="leg_right_1_link">
    <material>Gazebo/FlatWhite</material>
  </gazebo>
  <gazebo reference="leg_right_2_link">
    <material>Gazebo/FlatWhite</material>
  </gazebo>
  <gazebo reference="leg_right_3_link">
    <material>Gazebo/FlatWhite</material>
  </gazebo>
  <!-- <gazebo reference="leg_${side}_4_link">
     <material>Gazebo/FlatBlack</material>
   </gazebo>
   <gazebo reference="leg_${side}_5_link">
     <material>Gazebo/FlatBlack</material>
   </gazebo> -->
  <gazebo reference="leg_right_length_link">
    <material>Gazebo/FlatBlack</material>
  </gazebo>
  <gazebo>
    <plugin filename="libroboticsgroup_gazebo_mimic_joint_plugin.so" name="mimic_joint_plugin">
      <joint>leg_right_length_joint</joint>
      <mimicJoint>leg_right_knee_joint</mimicJoint>
      <multiplier>3.38877</multiplier>
      <offset>-0.19229</offset>
      <sensitiveness>0.0</sensitiveness>
      <!-- if absolute difference between setpoint and process value is below this threshold, do nothing; 0.0 = disable [rad] -->
      <maxEffort>100.0</maxEffort>
    </plugin>
  </gazebo>
  <gazebo>
    <plugin filename="libroboticsgroup_gazebo_mimic_joint_plugin.so" name="mimic_joint_plugin">
      <joint>leg_right_length_joint</joint>
      <mimicJoint>leg_right_femur_joint</mimicJoint>
      <multiplier>1.69435</multiplier>
      <offset>-0.096145</offset>
      <sensitiveness>0.0</sensitiveness>
      <!-- if absolute difference between setpoint and process value is below this threshold, do nothing; 0.0 = disable [rad] -->
      <maxEffort>100.0</maxEffort>
    </plugin>
  </gazebo>
  <gazebo>
    <plugin filename="libgazebo_ros_control.so" name="gazebo_ros_control">
      <ns/>
      <robotSimType>pal_hardware_gazebo/PalHardwareGazebo</robotSimType>
      <robotNamespace/>
      <controlPeriod>0.001</controlPeriod>
    </plugin>
  </gazebo>
  <gazebo>
    <plugin filename="libgazebo_world_odometry.so" name="gazebo_ros_odometry">
      <frameName>base_link</frameName>
      <topicName>floating_base_pose_simulated</topicName>
    </plugin>
  </gazebo>
  <gazebo>
    <plugin filename="libgazebo_ros_force.so" name="gazebo_ros_force">
      <bodyName>base_link</bodyName>
      <topicName>wrench</topicName>
    </plugin>
  </gazebo>
  <gazebo reference="imu_link">
    <!-- this is expected to be reparented to pelvis with appropriate offset
         when imu_link is reduced by fixed joint reduction -->
    <!-- todo: this is working with gazebo 1.4, need to write a unit test -->
    <sensor name="imu_sensor" type="imu">
      <always_on>1</always_on>
      <update_rate>1000.0</update_rate>
      <imu>
        <noise>
          <type>gaussian</type>
          <!-- Noise parameters from Boston Dynamics
               (http://gazebosim.org/wiki/Sensor_noise):
                 rates (rad/s): mean=0, stddev=2e-4
                 accels (m/s/s): mean=0, stddev=1.7e-2
                 rate bias (rad/s): 5e-6 - 1e-5
                 accel bias (m/s/s): 1e-1
               Experimentally, simulation provide rates with noise of
               about 1e-3 rad/s and accels with noise of about 1e-1 m/s/s.
               So we don't expect to see the noise unless number of inner iterations
               are increased.

               We will add bias.  In this model, bias is sampled once for rates
               and once for accels at startup; the sign (negative or positive)
               of each bias is then switched with equal probability.  Thereafter,
               the biases are fixed additive offsets.  We choose
               bias means and stddevs to produce biases close to the provided
               data. -->
          <!--
          <rate>
            <mean>0.0</mean>
            <stddev>2e-4</stddev>
            <bias_mean>0.0000075</bias_mean>
            <bias_stddev>0.0000008</bias_stddev>
          </rate>
          <accel>
            <mean>0.0</mean>
            <stddev>1.7e-2</stddev>
            <bias_mean>0.1</bias_mean>
            <bias_stddev>0.001</bias_stddev>
          </accel>
          -->
          <rate>
            <mean>0.0</mean>
            <stddev>0.0</stddev>
            <bias_mean>0.000000</bias_mean>
            <bias_stddev>0.0000008</bias_stddev>
          </rate>
          <accel>
            <mean>0.0</mean>
            <stddev>0.0</stddev>
            <bias_mean>0.0</bias_mean>
            <bias_stddev>0.000</bias_stddev>
          </accel>
        </noise>
      </imu>
    </sensor>
  </gazebo>
  <!-- define global properties -->
  <!-- <xacro:property name="M_PI" value="3.1415926535897931" /> -->
  <material name="Blue">
    <color rgba="0.0 0.0 0.8 1.0"/>
  </material>
  <material name="Green">
    <color rgba="0.0 0.8 0.0 1.0"/>
  </material>
  <material name="Grey">
    <color rgba="0.7 0.7 0.7 1.0"/>
  </material>
  <material name="LightGrey">
    <color rgba="0.9 0.9 0.9 1.0"/>
  </material>
  <material name="DarkGrey">
    <color rgba="0.2 0.2 0.2 1.0"/>
  </material>
  <material name="Red">
    <color rgba="0.8 0.0 0.0 1.0"/>
  </material>
  <material name="White">
    <color rgba="1.0 1.0 1.0 1.0"/>
  </material>
  <material name="Orange">
    <color rgba="1.0 0.5 0.0 1.0"/>
  </material>
  
  
  <link name="world"/>
  <joint name="reference" type="floating">
    <parent link="world"/>
    <child link="base_link"/>
  </joint>
  
  <link name="leg_left_knee_lower_bearing"/>
    <joint name="leg_left_knee_lower_bearing_joint" type="fixed">
    	<parent link="leg_left_knee_link"/>
    	<child link="leg_left_knee_lower_bearing"/>
    	<origin rpy="0 0 0" xyz="-0.375 0.0 -0.067"/>
    </joint>
    
    <link name="leg_right_knee_lower_bearing"/>
    <joint name="leg_right_knee_lower_bearing_joint" type="fixed">
    	<parent link="leg_right_knee_link"/>
    	<child link="leg_right_knee_lower_bearing"/>
    	<origin rpy="0 0 0" xyz="-0.375 0.0 -0.067"/>
    </joint>
  
</robot>

